[2025-01-03T07:13:51.750+0000] {taskinstance.py:1956} INFO - Dependencies all met for dep_context=non-requeueable deps ti=<TaskInstance: insert_data.ft_posting_f scheduled__2024-12-31T00:00:00+00:00 [queued]>
[2025-01-03T07:13:51.787+0000] {taskinstance.py:1956} INFO - Dependencies all met for dep_context=requeueable deps ti=<TaskInstance: insert_data.ft_posting_f scheduled__2024-12-31T00:00:00+00:00 [queued]>
[2025-01-03T07:13:51.788+0000] {taskinstance.py:2170} INFO - Starting attempt 1 of 3
[2025-01-03T07:16:04.946+0000] {taskinstance.py:2191} INFO - Executing <Task(PythonOperator): ft_posting_f> on 2024-12-31 00:00:00+00:00
[2025-01-03T07:16:09.651+0000] {standard_task_runner.py:60} INFO - Started process 128 to run task
[2025-01-03T07:16:09.656+0000] {standard_task_runner.py:87} INFO - Running: ['***', 'tasks', 'run', 'insert_data', 'ft_posting_f', 'scheduled__2024-12-31T00:00:00+00:00', '--job-id', '188', '--raw', '--subdir', 'DAGS_FOLDER/insert_data.py', '--cfg-path', '/tmp/tmpntk9z2_s']
[2025-01-03T07:16:09.678+0000] {standard_task_runner.py:88} INFO - Job 188: Subtask ft_posting_f
[2025-01-03T07:16:09.880+0000] {task_command.py:423} INFO - Running <TaskInstance: insert_data.ft_posting_f scheduled__2024-12-31T00:00:00+00:00 [running]> on host 403e7aadd7ee
[2025-01-03T07:16:19.146+0000] {taskinstance.py:2480} INFO - Exporting env vars: AIRFLOW_CTX_DAG_OWNER='agushchin' AIRFLOW_CTX_DAG_ID='insert_data' AIRFLOW_CTX_TASK_ID='ft_posting_f' AIRFLOW_CTX_EXECUTION_DATE='2024-12-31T00:00:00+00:00' AIRFLOW_CTX_TRY_NUMBER='1' AIRFLOW_CTX_DAG_RUN_ID='scheduled__2024-12-31T00:00:00+00:00'
[2025-01-03T07:16:20.238+0000] {base.py:83} INFO - Using connection ID 'postgres-db' for task execution.
[2025-01-03T07:16:52.530+0000] {taskinstance.py:2698} ERROR - Task failed with exception
Traceback (most recent call last):
  File "/home/airflow/.local/lib/python3.8/site-packages/sqlalchemy/engine/base.py", line 1910, in _execute_context
    self.dialect.do_execute(
  File "/home/airflow/.local/lib/python3.8/site-packages/sqlalchemy/engine/default.py", line 736, in do_execute
    cursor.execute(statement, parameters)
psycopg2.errors.UniqueViolation: duplicate key value violates unique constraint "pg_type_typname_nsp_index"
DETAIL:  Key (typname, typnamespace)=(ft_posting_f, 17018) already exists.


The above exception was the direct cause of the following exception:

Traceback (most recent call last):
  File "/home/airflow/.local/lib/python3.8/site-packages/airflow/models/taskinstance.py", line 433, in _execute_task
    result = execute_callable(context=context, **execute_callable_kwargs)
  File "/home/airflow/.local/lib/python3.8/site-packages/airflow/operators/python.py", line 199, in execute
    return_value = self.execute_callable()
  File "/home/airflow/.local/lib/python3.8/site-packages/airflow/operators/python.py", line 216, in execute_callable
    return self.python_callable(*self.op_args, **self.op_kwargs)
  File "/opt/airflow/dags/insert_data.py", line 21, in insert_data
    df.to_sql(table_name, engine, schema="stage", if_exists="append", index=False)
  File "/home/airflow/.local/lib/python3.8/site-packages/pandas/core/generic.py", line 2878, in to_sql
    return sql.to_sql(
  File "/home/airflow/.local/lib/python3.8/site-packages/pandas/io/sql.py", line 769, in to_sql
    return pandas_sql.to_sql(
  File "/home/airflow/.local/lib/python3.8/site-packages/pandas/io/sql.py", line 1910, in to_sql
    table = self.prep_table(
  File "/home/airflow/.local/lib/python3.8/site-packages/pandas/io/sql.py", line 1814, in prep_table
    table.create()
  File "/home/airflow/.local/lib/python3.8/site-packages/pandas/io/sql.py", line 914, in create
    self._execute_create()
  File "/home/airflow/.local/lib/python3.8/site-packages/pandas/io/sql.py", line 900, in _execute_create
    self.table.create(bind=self.pd_sql.con)
  File "/home/airflow/.local/lib/python3.8/site-packages/sqlalchemy/sql/schema.py", line 962, in create
    bind._run_ddl_visitor(ddl.SchemaGenerator, self, checkfirst=checkfirst)
  File "/home/airflow/.local/lib/python3.8/site-packages/sqlalchemy/engine/base.py", line 2221, in _run_ddl_visitor
    visitorcallable(self.dialect, self, **kwargs).traverse_single(element)
  File "/home/airflow/.local/lib/python3.8/site-packages/sqlalchemy/sql/visitors.py", line 524, in traverse_single
    return meth(obj, **kw)
  File "/home/airflow/.local/lib/python3.8/site-packages/sqlalchemy/sql/ddl.py", line 899, in visit_table
    self.connection.execute(
  File "/home/airflow/.local/lib/python3.8/site-packages/sqlalchemy/engine/base.py", line 1385, in execute
    return meth(self, multiparams, params, _EMPTY_EXECUTION_OPTS)
  File "/home/airflow/.local/lib/python3.8/site-packages/sqlalchemy/sql/ddl.py", line 80, in _execute_on_connection
    return connection._execute_ddl(
  File "/home/airflow/.local/lib/python3.8/site-packages/sqlalchemy/engine/base.py", line 1477, in _execute_ddl
    ret = self._execute_context(
  File "/home/airflow/.local/lib/python3.8/site-packages/sqlalchemy/engine/base.py", line 1953, in _execute_context
    self._handle_dbapi_exception(
  File "/home/airflow/.local/lib/python3.8/site-packages/sqlalchemy/engine/base.py", line 2134, in _handle_dbapi_exception
    util.raise_(
  File "/home/airflow/.local/lib/python3.8/site-packages/sqlalchemy/util/compat.py", line 211, in raise_
    raise exception
  File "/home/airflow/.local/lib/python3.8/site-packages/sqlalchemy/engine/base.py", line 1910, in _execute_context
    self.dialect.do_execute(
  File "/home/airflow/.local/lib/python3.8/site-packages/sqlalchemy/engine/default.py", line 736, in do_execute
    cursor.execute(statement, parameters)
sqlalchemy.exc.IntegrityError: (psycopg2.errors.UniqueViolation) duplicate key value violates unique constraint "pg_type_typname_nsp_index"
DETAIL:  Key (typname, typnamespace)=(ft_posting_f, 17018) already exists.

[SQL: 
CREATE TABLE stage.ft_posting_f (
	"OPER_DATE" TEXT, 
	"CREDIT_ACCOUNT_RK" BIGINT, 
	"DEBET_ACCOUNT_RK" BIGINT, 
	"CREDIT_AMOUNT" FLOAT(53), 
	"DEBET_AMOUNT" FLOAT(53)
)

]
(Background on this error at: https://sqlalche.me/e/14/gkpj)
[2025-01-03T07:16:52.546+0000] {taskinstance.py:1138} INFO - Marking task as UP_FOR_RETRY. dag_id=insert_data, task_id=ft_posting_f, execution_date=20241231T000000, start_date=20250103T071351, end_date=20250103T071652
[2025-01-03T07:16:52.557+0000] {standard_task_runner.py:107} ERROR - Failed to execute job 188 for task ft_posting_f ((psycopg2.errors.UniqueViolation) duplicate key value violates unique constraint "pg_type_typname_nsp_index"
DETAIL:  Key (typname, typnamespace)=(ft_posting_f, 17018) already exists.

[SQL: 
CREATE TABLE stage.ft_posting_f (
	"OPER_DATE" TEXT, 
	"CREDIT_ACCOUNT_RK" BIGINT, 
	"DEBET_ACCOUNT_RK" BIGINT, 
	"CREDIT_AMOUNT" FLOAT(53), 
	"DEBET_AMOUNT" FLOAT(53)
)

]
(Background on this error at: https://sqlalche.me/e/14/gkpj); 128)
[2025-01-03T07:16:52.581+0000] {local_task_job_runner.py:234} INFO - Task exited with return code 1
[2025-01-03T07:16:52.605+0000] {taskinstance.py:3280} INFO - 0 downstream tasks scheduled from follow-on schedule check
