[2024-12-30T17:47:12.979+0000] {taskinstance.py:1956} INFO - Dependencies all met for dep_context=non-requeueable deps ti=<TaskInstance: insert_data.call_clear_all_data scheduled__2024-12-29T00:00:00+00:00 [queued]>
[2024-12-30T17:47:12.996+0000] {taskinstance.py:1956} INFO - Dependencies all met for dep_context=requeueable deps ti=<TaskInstance: insert_data.call_clear_all_data scheduled__2024-12-29T00:00:00+00:00 [queued]>
[2024-12-30T17:47:12.996+0000] {taskinstance.py:2170} INFO - Starting attempt 2 of 3
[2024-12-30T17:47:13.026+0000] {taskinstance.py:2191} INFO - Executing <Task(SQLExecuteQueryOperator): call_clear_all_data> on 2024-12-29 00:00:00+00:00
[2024-12-30T17:47:13.037+0000] {standard_task_runner.py:60} INFO - Started process 427 to run task
[2024-12-30T17:47:13.041+0000] {standard_task_runner.py:87} INFO - Running: ['***', 'tasks', 'run', 'insert_data', 'call_clear_all_data', 'scheduled__2024-12-29T00:00:00+00:00', '--job-id', '23', '--raw', '--subdir', 'DAGS_FOLDER/insert_data.py', '--cfg-path', '/tmp/tmpkv7p0xhi']
[2024-12-30T17:47:13.045+0000] {standard_task_runner.py:88} INFO - Job 23: Subtask call_clear_all_data
[2024-12-30T17:47:13.632+0000] {task_command.py:423} INFO - Running <TaskInstance: insert_data.call_clear_all_data scheduled__2024-12-29T00:00:00+00:00 [running]> on host 403e7aadd7ee
[2024-12-30T17:47:13.773+0000] {taskinstance.py:2480} INFO - Exporting env vars: AIRFLOW_CTX_DAG_OWNER='agushchin' AIRFLOW_CTX_DAG_ID='insert_data' AIRFLOW_CTX_TASK_ID='call_clear_all_data' AIRFLOW_CTX_EXECUTION_DATE='2024-12-29T00:00:00+00:00' AIRFLOW_CTX_TRY_NUMBER='2' AIRFLOW_CTX_DAG_RUN_ID='scheduled__2024-12-29T00:00:00+00:00'
[2024-12-30T17:47:13.776+0000] {sql.py:276} INFO - Executing: CALL dm.clear_all_data()
[2024-12-30T17:47:13.793+0000] {base.py:83} INFO - Using connection ID 'postgres-db' for task execution.
[2024-12-30T17:47:13.816+0000] {base.py:83} INFO - Using connection ID 'postgres-db' for task execution.
[2024-12-30T17:47:13.839+0000] {sql.py:450} INFO - Running statement: CALL dm.clear_all_data(), parameters: None
[2024-12-30T17:47:13.846+0000] {taskinstance.py:2698} ERROR - Task failed with exception
Traceback (most recent call last):
  File "/home/airflow/.local/lib/python3.8/site-packages/airflow/models/taskinstance.py", line 433, in _execute_task
    result = execute_callable(context=context, **execute_callable_kwargs)
  File "/home/airflow/.local/lib/python3.8/site-packages/airflow/providers/common/sql/operators/sql.py", line 282, in execute
    output = hook.run(
  File "/home/airflow/.local/lib/python3.8/site-packages/airflow/providers/common/sql/hooks/sql.py", line 398, in run
    self._run_command(cur, sql_statement, parameters)
  File "/home/airflow/.local/lib/python3.8/site-packages/airflow/providers/common/sql/hooks/sql.py", line 455, in _run_command
    cur.execute(sql_statement)
psycopg2.errors.InvalidSchemaName: schema "dm" does not exist
LINE 1: CALL dm.clear_all_data()
             ^

[2024-12-30T17:47:13.869+0000] {taskinstance.py:1138} INFO - Marking task as UP_FOR_RETRY. dag_id=insert_data, task_id=call_clear_all_data, execution_date=20241229T000000, start_date=20241230T174712, end_date=20241230T174713
[2024-12-30T17:47:13.894+0000] {standard_task_runner.py:107} ERROR - Failed to execute job 23 for task call_clear_all_data (schema "dm" does not exist
LINE 1: CALL dm.clear_all_data()
             ^
; 427)
[2024-12-30T17:47:13.940+0000] {local_task_job_runner.py:234} INFO - Task exited with return code 1
[2024-12-30T17:47:14.223+0000] {taskinstance.py:3280} INFO - 0 downstream tasks scheduled from follow-on schedule check
