[2025-01-05T09:39:53.997+0000] {scheduler_job_runner.py:1586} WARNING - Marking task instance <TaskInstance: insert_data.sql_start_to_log scheduled__2025-01-04T00:00:00+00:00 [queued]> stuck in queued as failed. If the task instance has available retries, it will be retried.
[2025-01-05T09:39:54.988+0000] {scheduler_job_runner.py:781} ERROR - Executor reports task instance <TaskInstance: insert_data.sql_start_to_log scheduled__2025-01-04T00:00:00+00:00 [queued]> finished (failed) although the task says it's queued. (Info: None) Was the task killed externally?
