[2024-12-30T17:46:26.733+0000] {taskinstance.py:1956} INFO - Dependencies all met for dep_context=non-requeueable deps ti=<TaskInstance: insert_data.call_clear_all_data manual__2024-12-30T17:42:06.451598+00:00 [queued]>
[2024-12-30T17:46:26.744+0000] {taskinstance.py:1956} INFO - Dependencies all met for dep_context=requeueable deps ti=<TaskInstance: insert_data.call_clear_all_data manual__2024-12-30T17:42:06.451598+00:00 [queued]>
[2024-12-30T17:46:26.745+0000] {taskinstance.py:2170} INFO - Starting attempt 2 of 4
[2024-12-30T17:46:26.785+0000] {taskinstance.py:2191} INFO - Executing <Task(SQLExecuteQueryOperator): call_clear_all_data> on 2024-12-30 17:42:06.451598+00:00
[2024-12-30T17:46:26.799+0000] {standard_task_runner.py:60} INFO - Started process 381 to run task
[2024-12-30T17:46:26.803+0000] {standard_task_runner.py:87} INFO - Running: ['***', 'tasks', 'run', 'insert_data', 'call_clear_all_data', 'manual__2024-12-30T17:42:06.451598+00:00', '--job-id', '19', '--raw', '--subdir', 'DAGS_FOLDER/insert_data.py', '--cfg-path', '/tmp/tmpl31s9j0t']
[2024-12-30T17:46:26.808+0000] {standard_task_runner.py:88} INFO - Job 19: Subtask call_clear_all_data
[2024-12-30T17:46:27.269+0000] {task_command.py:423} INFO - Running <TaskInstance: insert_data.call_clear_all_data manual__2024-12-30T17:42:06.451598+00:00 [running]> on host 403e7aadd7ee
[2024-12-30T17:46:27.370+0000] {taskinstance.py:2480} INFO - Exporting env vars: AIRFLOW_CTX_DAG_OWNER='agushchin' AIRFLOW_CTX_DAG_ID='insert_data' AIRFLOW_CTX_TASK_ID='call_clear_all_data' AIRFLOW_CTX_EXECUTION_DATE='2024-12-30T17:42:06.451598+00:00' AIRFLOW_CTX_TRY_NUMBER='2' AIRFLOW_CTX_DAG_RUN_ID='manual__2024-12-30T17:42:06.451598+00:00'
[2024-12-30T17:46:27.371+0000] {sql.py:276} INFO - Executing: CALL dm.clear_all_data()
[2024-12-30T17:46:27.382+0000] {base.py:83} INFO - Using connection ID 'postgres-db' for task execution.
[2024-12-30T17:46:27.391+0000] {base.py:83} INFO - Using connection ID 'postgres-db' for task execution.
[2024-12-30T17:46:27.404+0000] {sql.py:450} INFO - Running statement: CALL dm.clear_all_data(), parameters: None
[2024-12-30T17:46:27.409+0000] {taskinstance.py:2698} ERROR - Task failed with exception
Traceback (most recent call last):
  File "/home/airflow/.local/lib/python3.8/site-packages/airflow/models/taskinstance.py", line 433, in _execute_task
    result = execute_callable(context=context, **execute_callable_kwargs)
  File "/home/airflow/.local/lib/python3.8/site-packages/airflow/providers/common/sql/operators/sql.py", line 282, in execute
    output = hook.run(
  File "/home/airflow/.local/lib/python3.8/site-packages/airflow/providers/common/sql/hooks/sql.py", line 398, in run
    self._run_command(cur, sql_statement, parameters)
  File "/home/airflow/.local/lib/python3.8/site-packages/airflow/providers/common/sql/hooks/sql.py", line 455, in _run_command
    cur.execute(sql_statement)
psycopg2.errors.InvalidSchemaName: schema "dm" does not exist
LINE 1: CALL dm.clear_all_data()
             ^

[2024-12-30T17:46:27.421+0000] {taskinstance.py:1138} INFO - Marking task as UP_FOR_RETRY. dag_id=insert_data, task_id=call_clear_all_data, execution_date=20241230T174206, start_date=20241230T174626, end_date=20241230T174627
[2024-12-30T17:46:27.460+0000] {standard_task_runner.py:107} ERROR - Failed to execute job 19 for task call_clear_all_data (schema "dm" does not exist
LINE 1: CALL dm.clear_all_data()
             ^
; 381)
[2024-12-30T17:46:27.502+0000] {local_task_job_runner.py:234} INFO - Task exited with return code 1
[2024-12-30T17:46:27.693+0000] {taskinstance.py:3280} INFO - 0 downstream tasks scheduled from follow-on schedule check
